Workbook

Sheet Tests
A1: N° | B1: Chapitre | C1: Formule (FR, telle qu’imprimée) | D1: Formule testée (EN) | E1: Résultat attendu | F1: Résultat obtenu | G1: Vérification
A2: 1 | B2: 5 | C2: =(2+3)*4 | D2: (2+3)*4 | E2: 20 | F2: =(2+3)*4 -> 20 | G2: =IF(F2=E2,"OK","À vérifier") -> OK
A3: 2 | B3: 5 | C3: =2+3*4 | D3: 2+3*4 | E3: 14 | F3: =2+3*4 -> 14 | G3: =IF(F3=E3,"OK","À vérifier") -> OK
A4: 3 | B4: 5 | C4: =A2&" "&B2 | D4: Data!R6&" "&Data!R7 | E4: Sami Exemple | F4: =Data!R6&" "&Data!R7 -> Sami Exemple | G4: =IF(F4=E4,"OK","À vérifier") -> OK
A5: 4 | B5: 6 | C5: =SOMME(C5:C10) | D5: SUM(Data!K2:K7) | E5: 601000 | F5: =SUM(Data!K2:K7) -> 601000 | G5: =IF(F5=E5,"OK","À vérifier") -> OK
A6: 5 | B6: 6 | C6: =MOYENNE(D5:D10) | D6: ROUND(AVERAGE(Data!L2:L7),2) | E6: 106166.67 | F6: =ROUND(AVERAGE(Data!L2:L7),2) -> 106166.67 | G6: =IF(F6=E6,"OK","À vérifier") -> OK
A7: 6 | B7: 6 | C7: =MAX(D5:D10) | D7: MAX(Data!L2:L7) | E7: 151000 | F7: =MAX(Data!L2:L7) -> 151000 | G7: =IF(F7=E7,"OK","À vérifier") -> OK
A8: 7 | B8: 6 | C8: =NB(…) | D8: COUNT(Data!I2:L7) | E8: 12 | F8: =COUNT(Data!I2:L7) -> 12 | G8: =IF(F8=E8,"OK","À vérifier") -> OK
A9: 8 | B9: 6 | C9: =NBVAL(…) | D9: COUNTA(Data!I2:I7) | E9: 6 | F9: =COUNTA(Data!I2:I7) -> 6 | G9: =IF(F9=E9,"OK","À vérifier") -> OK
A10: 9 | B10: 6 | C10: =ARRONDI(B2;2) | D10: ROUND(2.456,2) | E10: 2.46 | F10: =ROUND(2.456,2) -> 2.46 | G10: =IF(F10=E10,"OK","À vérifier") -> OK
A11: 10 | B11: 7 | C11: =SI(B2>=10;"Admis";"Ajourné") | D11: IF(Data!N2>=10,"Admis","Ajourné") | E11: Admis | F11: =IF(Data!N2>=10,"Admis","Ajourné") -> Admis | G11: =IF(F11=E11,"OK","À vérifier") -> OK
A12: 11 | B12: 7 | C12: =SI(B3>=10;"Admis";"Ajourné") | D12: IF(Data!N3>=10,"Admis","Ajourné") | E12: Ajourné | F12: =IF(Data!N3>=10,"Admis","Ajourné") -> Ajourné | G12: =IF(F12=E12,"OK","À vérifier") -> OK
A13: 12 | B13: 7 | C13: =SI(ET(B2>=10;C2>=10);"Validé";"Non validé") | D13: IF(AND(Data!N2>=10,Data!N4>=10),"Validé","Non validé") | E13: Validé | F13: =IF(AND(Data!N2>=10,Data!N4>=10),"Validé","Non validé") -> Validé | G13: =IF(F13=E13,"OK","À vérifier") -> OK
A14: 13 | B14: 7 | C14: =SI(OU(K5="Rupture";K5="À commander");"Commander";"") | D14: IF(OR("À commander"="Rupture","À commander"="À commander"),"Commander","") | E14: Commander | F14: =IF(OR("À commander"="Rupture","À commander"="À commander"),"Commander","") -> Commander | G14: =IF(F14=E14,"OK","À vérifier") -> OK
A15: 14 | B15: 7 | C15: SI imbriqués (H7 = 12,75) | D15: IF(Data!N4>=16,"Très bien",IF(Data!N4>=14,"Bien",IF(Data!N4>=12,"Assez bien",IF(Data!N4>=10,"Passable","")))) | E15: Assez bien | F15: =IF(Data!N4>=16,"Très bien",IF(Data!N4>=14,"Bien",IF(Data!N4>=12,"Assez bien",IF(Data!N4>=10,"Passable","")))) -> Assez bien | G15: =IF(F15=E15,"OK","À vérifier") -> OK
A16: 15 | B16: 7 | C16: =SI.CONDITIONS(…) (H7 = 14,1) | D16: _xlfn.IFS(Data!N6>=16,"Très bien",Data!N6>=14,"Bien",Data!N6>=12,"Assez bien",Data!N6>=10,"Passable",TRUE,"") | E16: Bien | F16: =_xlfn.IFS(Data!N6>=16,"Très bien",Data!N6>=14,"Bien",Data!N6>=12,"Assez bien",Data!N6>=10,"Passable",TRUE(),"") -> Bien | G16: =IF(F16=E16,"OK","À vérifier") -> OK
A17: 16 | B17: 7 | C17: =NB.SI(B5:B10;"Commercial") | D17: COUNTIF(Data!J2:J7,"Commercial") | E17: 4 | F17: =COUNTIF(Data!J2:J7,"Commercial") -> 4 | G17: =IF(F17=E17,"OK","À vérifier") -> OK
A18: 17 | B18: 7 | C18: =SOMME.SI(B5:B10;"Marketing";C5:C10) | D18: SUMIF(Data!J2:J7,"Marketing",Data!K2:K7) | E18: 130000 | F18: =SUMIF(Data!J2:J7,"Marketing",Data!K2:K7) -> 130000 | G18: =IF(F18=E18,"OK","À vérifier") -> OK
A19: 18 | B19: 7 | C19: =SOMME.SI.ENS(…;"Commercial";…;">100000") | D19: SUMIFS(Data!K2:K7,Data!J2:J7,"Commercial",Data!L2:L7,">100000") | E19: 373000 | F19: =SUMIFS(Data!K2:K7,Data!J2:J7,"Commercial",Data!L2:L7,">100000") -> 373000 | G19: =IF(F19=E19,"OK","À vérifier") -> OK
A20: 19 | B20: 7 | C20: =NB.SI.ENS(…;"Commercial";…;">100000") | D20: COUNTIFS(Data!J2:J7,"Commercial",Data!L2:L7,">100000") | E20: 3 | F20: =COUNTIFS(Data!J2:J7,"Commercial",Data!L2:L7,">100000") -> 3 | G20: =IF(F20=E20,"OK","À vérifier") -> OK
A21: 20 | B21: 7 | C21: =MOYENNE.SI(…;"Marketing";…) | D21: AVERAGEIF(Data!J2:J7,"Marketing",Data!K2:K7) | E21: 65000 | F21: =AVERAGEIF(Data!J2:J7,"Marketing",Data!K2:K7) -> 65000 | G21: =IF(F21=E21,"OK","À vérifier") -> OK
A22: 21 | B22: 7 | C22: =SIERREUR(B2/C2;0) | D22: IFERROR(1/0,0) | E22: 0 | F22: =IFERROR(1/0,0) -> 0 | G22: =IF(F22=E22,"OK","À vérifier") -> OK
A23: 22 | B23: 13 | C23: SOMME.SI.ENS avec "*" (Toutes) | D23: SUMIFS(Data!K2:K7,Data!J2:J7,"*") | E23: 601000 | F23: =SUMIFS(Data!K2:K7,Data!J2:J7,"*") -> 601000 | G23: =IF(F23=E23,"OK","À vérifier") -> OK
A24: 23 | B24: 8 | C24: =RECHERCHEV(B13;$A$5:$D$10;2;FAUX) | D24: VLOOKUP("P004",Data!D2:G7,2,FALSE) | E24: Ramette A4 | F24: =VLOOKUP("P004",Data!D2:G7,2,FALSE()) -> Ramette A4 | G24: =IF(F24=E24,"OK","À vérifier") -> OK
A25: 24 | B25: 8 | C25: =RECHERCHEV(…;3;FAUX) | D25: VLOOKUP("P004",Data!D2:G7,3,FALSE) | E25: 750 | F25: =VLOOKUP("P004",Data!D2:G7,3,FALSE()) -> 750 | G25: =IF(F25=E25,"OK","À vérifier") -> OK
A26: 25 | B26: 8 | C26: =EQUIV("C";A1:A3;0) | D26: MATCH("C",Data!A1:A3,0) | E26: 3 | F26: =MATCH("C",Data!A1:A3,0) -> 3 | G26: =IF(F26=E26,"OK","À vérifier") -> OK
A27: 26 | B27: 8 | C27: =INDEX(B5:B10;4) | D27: INDEX(Data!E2:E7,4) | E27: Ramette A4 | F27: =INDEX(Data!E2:E7,4) -> Ramette A4 | G27: =IF(F27=E27,"OK","À vérifier") -> OK
A28: 27 | B28: 8 | C28: =INDEX(B5:B10;EQUIV(B13;A5:A10;0)) (P006) | D28: INDEX(Data!E2:E7,MATCH("P006",Data!D2:D7,0)) | E28: Calculatrice | F28: =INDEX(Data!E2:E7,MATCH("P006",Data!D2:D7,0)) -> Calculatrice | G28: =IF(F28=E28,"OK","À vérifier") -> OK
A29: 28 | B29: 8 | C29: =INDEX(B7:B22;EQUIV(MAX(H7:H22);H7:H22;0)) | D29: INDEX(Data!M2:M6,MATCH(MAX(Data!N2:N6),Data!N2:N6,0)) | E29: Amine | F29: =INDEX(Data!M2:M6,MATCH(MAX(Data!N2:N6),Data!N2:N6,0)) -> Amine | G29: =IF(F29=E29,"OK","À vérifier") -> OK
A30: 29 | B30: 8 | C30: =RECHERCHEX(B13;A5:A10;B5:B10;"Introuvable") | D30: — | E30: Ramette A4 (MANUEL : Microsoft 365 / Excel 2021+) | F30: — | G30: MANUEL
A31: 30 | B31: 9 | C31: =SUPPRESPACE(" sami EXEMPLE ") | D31: TRIM(Data!R2) | E31: sami EXEMPLE | F31: =TRIM(Data!R2) -> sami EXEMPLE | G31: =IF(F31=E31,"OK","À vérifier") -> OK
A32: 31 | B32: 9 | C32: =NOMPROPRE(SUPPRESPACE(A5)) | D32: PROPER(TRIM(Data!R2)) | E32: Sami Exemple | F32: =PROPER(TRIM(Data!R2)) -> Sami Exemple | G32: =IF(F32=E32,"OK","À vérifier") -> OK
A33: 32 | B33: 9 | C33: =MAJUSCULE("p004") | D33: UPPER("p004") | E33: P004 | F33: =UPPER("p004") -> P004 | G33: =IF(F33=E33,"OK","À vérifier") -> OK
A34: 33 | B34: 9 | C34: =GAUCHE("P004-ALG";4) | D34: LEFT(Data!R4,4) | E34: P004 | F34: =LEFT(Data!R4,4) -> P004 | G34: =IF(F34=E34,"OK","À vérifier") -> OK
A35: 34 | B35: 9 | C35: =STXT("F-2026-0042";3;4) | D35: MID(Data!R5,3,4) | E35: 2026 | F35: =MID(Data!R5,3,4) -> 2026 | G35: =IF(F35=E35,"OK","À vérifier") -> OK
A36: 35 | B36: 9 | C36: =NBCAR("Excel") | D36: LEN("Excel") | E36: 5 | F36: =LEN("Excel") -> 5 | G36: =IF(F36=E36,"OK","À vérifier") -> OK
A37: 36 | B37: 9 | C37: =TROUVE(" ";"Sami Exemple") | D37: FIND(" ",Data!R3) | E37: 5 | F37: =FIND(" ",Data!R3) -> 5 | G37: =IF(F37=E37,"OK","À vérifier") -> OK
A38: 37 | B38: 9 | C38: =GAUCHE(B5;TROUVE(" ";B5)-1) | D38: LEFT(Data!R3,FIND(" ",Data!R3)-1) | E38: Sami | F38: =LEFT(Data!R3,FIND(" ",Data!R3)-1) -> Sami | G38: =IF(F38=E38,"OK","À vérifier") -> OK
A39: 38 | B39: 9 | C39: =MAJUSCULE(GAUCHE(C5;3)) | D39: UPPER(LEFT(Data!R6,3)) | E39: SAM | F39: =UPPER(LEFT(Data!R6,3)) -> SAM | G39: =IF(F39=E39,"OK","À vérifier") -> OK
A40: 39 | B40: 9 | C40: =DATEDIF(A2;date;"y") | D40: DATEDIF(Data!P2,Data!P5,"y") | E40: 28 | F40: =DATEDIF(Data!P2,Data!P5,"y") -> 28 | G40: =IF(F40=E40,"OK","À vérifier") -> OK
...

Sheet Data
A1: A | D1: Code | E1: Produit | F1: Prix | G1: Stock | I1: Employé | J1: Service | K1: T1 | L1: T2 | M1: Élève | N1: Moyenne | P1: Dates | R1: Textes | T1: Notes / coefficients
A2: B | D2: P001 | E2: Cahier | F2: 120 | G2: 80 | I2: Ali | J2: Commercial | K2: 120000 | L2: 135000 | M2: Amine | N2: 16.96 | P2: 35868 | R2: sami EXEMPLE | T2: 17.5 | U2: 17.75 | V2: 16.75 | W2: 18.25 | X2: 13.75
A3: C | D3: P002 | E3: Stylo | F3: 30 | G3: 300 | I3: Fatima | J3: Commercial | K3: 98000 | L3: 87000 | M3: Sara | N3: 9.4 | P3: 46296 | R3: Sami Exemple | T3: 4 | U3: 3 | V3: 3 | W3: 2 | X3: 2
D4: P003 | E4: Classeur | F4: 250 | G4: 45 | I4: Hamza | J4: Marketing | K4: 76000 | L4: 99000 | M4: Yacine | N4: 12.75 | P4: 46326 | R4: P004-ALG
D5: P004 | E5: Ramette A4 | F5: 750 | G5: 20 | I5: Salma | J5: Commercial | K5: 143000 | L5: 151000 | M5: Lina | N5: 8.2 | P5: 46300 | R5: F-2026-0042
D6: P005 | E6: Agenda | F6: 400 | G6: 15 | I6: Youssef | J6: Marketing | K6: 54000 | L6: 61000 | M6: Omar | N6: 14.1 | R6: Sami
D7: P006 | E7: Calculatrice | F7: 1200 | G7: 9 | I7: Asma | J7: Commercial | K7: 110000 | L7: 104000 | R7: Exemple
